Workbook

Sheet Nike_Sales_Uncleaned
A1: Order_ID | B1: Gender_Category | C1: Product_Line | D1: Product_Name | E1: Size | F1: Units_Sold | G1: MRP | H1: Discount_Applied | I1: Revenue | J1: Order_Date | K1: Sales_Channel | L1: Region | M1: Profit
A2: 2000 | B2: Kids | C2: Training | D2: SuperRep Go | E2: M | H2: 0.47 | I2: 0 | J2: 45360 | K2: Online | L2: bengaluru | M2: -770.45
A3: 2001 | B3: Women | C3: Soccer | D3: Tiempo Legend | E3: M | F3: 3 | G3: 4957.93 | I3: 0 | J3: 45482 | K3: Retail | L3: Hyd | M3: -112.53
A4: 2002 | B4: Women | C4: Soccer | D4: Premier III | E4: M | F4: 4 | I4: 0 | K4: Retail | L4: Mumbai | M4: 3337.34
A5: 2003 | B5: Kids | C5: Lifestyle | D5: Blazer Mid | E5: L | G5: 9673.57 | I5: 0 | J5: 45569 | K5: Online | L5: Pune | M5: 3376.85
A6: 2004 | B6: Kids | C6: Running | D6: React Infinity | E6: XL | I6: 0 | J6: 45547 | K6: Retail | L6: Delhi | M6: 187.89
A7: 2005 | B7: Women | C7: Training | D7: Flex Trainer | E7: M | F7: 1 | G7: 7363.96 | I7: 0 | K7: Retail | L7: Delhi | M7: 1415.98
A8: 2006 | B8: Men | C8: Training | D8: SuperRep Go | E8: M | G8: 6819.78 | I8: 0 | J8: 45812 | K8: Online | L8: Bangalore | M8: 1802.09
A9: 2007 | B9: Kids | C9: Training | D9: SuperRep Go | E9: M | F9: 1 | H9: 0.32 | I9: 0 | K9: Retail | L9: Bangalore | M9: 2928.36
A10: 2008 | B10: Women | C10: Soccer | D10: Premier III | E10: 11 | F10: -1 | I10: 0 | J10: 45576 | K10: Online | L10: Hyderabad | M10: -731.18
A11: 2009 | B11: Men | C11: Soccer | D11: Mercurial Superfly | E11: M | F11: 4 | I11: 0 | K11: Online | L11: Pune | M11: 3929.61
A12: 2010 | B12: Kids | C12: Lifestyle | D12: Waffle One | E12: L | F12: 1 | G12: 7949.83 | I12: 0 | J12: 45673 | K12: Online | L12: Pune | M12: 1965.56
A13: 2011 | B13: Women | C13: Training | D13: Flex Trainer | E13: L | F13: -1 | G13: 9586.08 | I13: 0 | K13: Retail | L13: Hyd | M13: 1667.08
A14: 2018 | B14: Kids | C14: Lifestyle | D14: Blazer Mid | F14: -1 | H14: 0.86 | I14: 0 | J14: 45609 | K14: Online | L14: Delhi | M14: 2109.48
A15: 2013 | B15: Kids | C15: Training | D15: SuperRep Go | G15: 9671.05 | I15: 0 | J15: 45554 | K15: Online | L15: hyderbad | M15: 299.34
A16: 2014 | B16: Women | C16: Running | D16: React Infinity | E16: 11 | I16: 0 | J16: 45759 | K16: Online | L16: Bangalore | M16: -1044.4
A17: 2015 | B17: Kids | C17: Basketball | D17: Air Jordan | G17: 3285.52 | I17: 0 | J17: 45808 | K17: Retail | L17: Kolkata | M17: 1193.21
A18: 2016 | B18: Women | C18: Basketball | D18: Air Jordan | E18: M | F18: 1 | G18: 9871.75 | H18: 0.3 | I18: 6910.22 | K18: Retail | L18: hyderbad | M18: 2452.69
A19: 2017 | B19: Women | C19: Basketball | D19: Air Jordan | E19: 9 | F19: 4 | I19: 0 | J19: 45733 | K19: Retail | L19: Delhi | M19: 1946.24
A20: 2018 | B20: Men | C20: Training | D20: Metcon 7 | E20: XL | F20: 0 | H20: 1.17 | I20: 0 | K20: Online | L20: bengaluru | M20: -966.89
A21: 2019 | B21: Kids | C21: Running | D21: Air Zoom | E21: 6 | F21: 0 | G21: 3424.06 | H21: 0.32 | I21: 0 | J21: 45674 | K21: Online | L21: Hyderabad | M21: 1915.24
A22: 2020 | B22: Kids | C22: Soccer | D22: Tiempo Legend | E22: L | F22: -1 | H22: 0.67 | I22: 0 | J22: 45744 | K22: Retail | L22: Mumbai | M22: 439.96
A23: 2021 | B23: Men | C23: Running | D23: Free RN | E23: L | F23: -1 | G23: 7086.7 | H23: 0.66 | I23: -2409.48 | J23: 45615 | K23: Retail | L23: Hyd | M23: -1120.49
A24: 2022 | B24: Women | C24: Soccer | D24: Premier III | E24: M | I24: 0 | J24: 45559 | K24: Online | L24: Pune | M24: 3427.16
A25: 2023 | B25: Men | C25: Lifestyle | D25: Waffle One | E25: M | G25: 5003.95 | I25: 0 | J25: 45667 | K25: Online | L25: Mumbai | M25: 1498.37
A26: 2024 | B26: Kids | C26: Training | D26: SuperRep Go | E26: XL | F26: 0 | H26: 0.5 | I26: 0 | J26: 45654 | K26: Retail | L26: Bangalore | M26: 1842.35
A27: 2025 | B27: Women | C27: Basketball | D27: Kyrie Flytrap | E27: M | F27: 3 | G27: 9820.5 | I27: 0 | K27: Retail | L27: Mumbai | M27: 1900.15
A28: 2026 | B28: Kids | C28: Lifestyle | D28: Blazer Mid | E28: XL | F28: 1 | H28: 0.16 | I28: 0 | J28: 45514 | K28: Retail | L28: Kolkata | M28: 2301.64
A29: 2027 | B29: Men | C29: Basketball | D29: Zoom Freak | E29: XL | H29: 0.22 | I29: 0 | K29: Online | L29: Pune | M29: -138.74
A30: 2028 | B30: Men | C30: Training | D30: Flex Trainer | E30: 12 | G30: 3270.23 | I30: 0 | K30: Retail | L30: Delhi | M30: -946.86
A31: 2029 | B31: Men | C31: Training | D31: ZoomX Invincible | E31: 12 | F31: 0 | I31: 0 | J31: 45227 | K31: Online | L31: Bangalore | M31: -185.67
A32: 2030 | B32: Men | C32: Soccer | D32: Phantom GT | E32: XL | H32: 1.05 | I32: 0 | J32: 45852 | K32: Retail | L32: Hyd | M32: -122.93
A33: 2031 | B33: Men | C33: Soccer | D33: Premier III | F33: 4 | G33: 3493.04 | H33: 0.82 | I33: 2514.99 | J33: 45421 | K33: Online | L33: Delhi | M33: 350.7
A34: 2032 | B34: Women | C34: Lifestyle | D34: Blazer Mid | E34: XL | F34: 1 | H34: 1.07 | I34: 0 | J34: 45758 | K34: Retail | L34: Mumbai | M34: -555.16
A35: 2033 | B35: Men | C35: Soccer | D35: Mercurial Superfly | E35: XL | F35: -1 | I35: 0 | K35: Retail | L35: Kolkata | M35: -1005.71
A36: 2034 | B36: Men | C36: Basketball | D36: Air Jordan | E36: 6 | G36: 6235.71 | I36: 0 | J36: 45777 | K36: Retail | L36: Delhi | M36: -267.37
A37: 2035 | B37: Kids | C37: Basketball | D37: Zoom Freak | F37: 4 | H37: 0.38 | I37: 0 | J37: 45613 | K37: Online | L37: Bangalore | M37: 2914.83
A38: 2036 | B38: Men | C38: Training | D38: Metcon 7 | F38: 3 | I38: 0 | J38: 45703 | K38: Retail | L38: Bangalore | M38: -143.8
A39: 2037 | B39: Kids | C39: Running | D39: Pegasus Turbo | E39: 7 | F39: 3 | G39: 5653.14 | H39: 1.01 | I39: -169.59 | K39: Retail | L39: Pune | M39: 2776.96
A40: 2038 | B40: Kids | C40: Running | D40: Free RN | F40: 0 | H40: 0.83 | I40: 0 | K40: Online | L40: Delhi | M40: 1163.21
...

Sheet Cleaned Data
A1: Order_ID | B1: Gender_Category | C1: Product_Line | D1: Product_Name | E1: Size | F1: Units_Sold | G1: MRP | H1: Discount_Applied | I1: Revenue | J1: Order_Date | K1: Sales_Channel | L1: Region | M1: Profit
A2: 2000 | B2: Kids | C2: Training | D2: SuperRep Go | E2: =IF(Nike_Sales_Uncleaned!E2="","NA",IF(OR(Nike_Sales_Uncleaned!E2=0,Nike_Sales_Uncleaned!E2=-1),"NA",UPPER(Nike_Sales_Uncleaned!E2))) -> M | F2: {=IF(Nike_Sales_Uncleaned!F2="",MEDIAN(_xlfn._xlws.FILTER(Nike_Sales_Uncleaned!$F$2:$F$2501,Nike_Sales_Uncleaned!$F$2:$F$2501>0)),Nike_Sales_Uncleaned!F2)} -> 2 | G2: {=IF(OR(Nike_Sales_Uncleaned!G2="",Nike_Sales_Uncleaned!G2<=0),MEDIAN(_xlfn._xlws.FILTER(Nike_Sales_Uncleaned!$G$2:$G$2501,Nike_Sales_Uncleaned!$G$2:$G$2501>0)),Nike_Sales_Uncleaned!G2)} -> 6110.03 | H2: =IF(Nike_Sales_Uncleaned!H2="",0,IF(AND(Nike_Sales_Uncleaned!H2>=0,Nike_Sales_Uncleaned!H2<=1),Nike_Sales_Uncleaned!H2,0)) -> 0.47 | I2: 0 | J2: =IF(Nike_Sales_Uncleaned[[#This Row],[Order_Date]]="","",Nike_Sales_Uncleaned[[#This Row],[Order_Date]]) -> 45360 | K2: Online | L2: Bangalore | M2: -770.45
A3: 2001 | B3: Women | C3: Soccer | D3: Tiempo Legend | E3: =IF(Nike_Sales_Uncleaned!E3="","NA",IF(OR(Nike_Sales_Uncleaned!E3=0,Nike_Sales_Uncleaned!E3=-1),"NA",UPPER(Nike_Sales_Uncleaned!E3))) -> M | F3: {=IF(Nike_Sales_Uncleaned!F3="",MEDIAN(_xlfn._xlws.FILTER(Nike_Sales_Uncleaned!$F$2:$F$2501,Nike_Sales_Uncleaned!$F$2:$F$2501>0)),Nike_Sales_Uncleaned!F3)} -> 3 | G3: {=IF(OR(Nike_Sales_Uncleaned!G3="",Nike_Sales_Uncleaned!G3<=0),MEDIAN(_xlfn._xlws.FILTER(Nike_Sales_Uncleaned!$G$2:$G$2501,Nike_Sales_Uncleaned!$G$2:$G$2501>0)),Nike_Sales_Uncleaned!G3)} -> 4957.93 | H3: =IF(Nike_Sales_Uncleaned!H3="",0,IF(AND(Nike_Sales_Uncleaned!H3>=0,Nike_Sales_Uncleaned!H3<=1),Nike_Sales_Uncleaned!H3,0)) -> 0 | I3: 0 | J3: =IF(Nike_Sales_Uncleaned[[#This Row],[Order_Date]]="","",Nike_Sales_Uncleaned[[#This Row],[Order_Date]]) -> 45482 | K3: Retail | L3: Hyderabad | M3: -112.53
A4: 2002 | B4: Women | C4: Soccer | D4: Premier III | E4: =IF(Nike_Sales_Uncleaned!E4="","NA",IF(OR(Nike_Sales_Uncleaned!E4=0,Nike_Sales_Uncleaned!E4=-1),"NA",UPPER(Nike_Sales_Uncleaned!E4))) -> M | F4: {=IF(Nike_Sales_Uncleaned!F4="",MEDIAN(_xlfn._xlws.FILTER(Nike_Sales_Uncleaned!$F$2:$F$2501,Nike_Sales_Uncleaned!$F$2:$F$2501>0)),Nike_Sales_Uncleaned!F4)} -> 4 | G4: {=IF(OR(Nike_Sales_Uncleaned!G4="",Nike_Sales_Uncleaned!G4<=0),MEDIAN(_xlfn._xlws.FILTER(Nike_Sales_Uncleaned!$G$2:$G$2501,Nike_Sales_Uncleaned!$G$2:$G$2501>0)),Nike_Sales_Uncleaned!G4)} -> 6110.03 | H4: =IF(Nike_Sales_Uncleaned!H4="",0,IF(AND(Nike_Sales_Uncleaned!H4>=0,Nike_Sales_Uncleaned!H4<=1),Nike_Sales_Uncleaned!H4,0)) -> 0 | I4: 0 | J4: =IF(Nike_Sales_Uncleaned[[#This Row],[Order_Date]]="","",Nike_Sales_Uncleaned[[#This Row],[Order_Date]]) | K4: Retail | L4: Mumbai | M4: 3337.34
A5: 2003 | B5: Kids | C5: Lifestyle | D5: Blazer Mid | E5: =IF(Nike_Sales_Uncleaned!E5="","NA",IF(OR(Nike_Sales_Uncleaned!E5=0,Nike_Sales_Uncleaned!E5=-1),"NA",UPPER(Nike_Sales_Uncleaned!E5))) -> L | F5: {=IF(Nike_Sales_Uncleaned!F5="",MEDIAN(_xlfn._xlws.FILTER(Nike_Sales_Uncleaned!$F$2:$F$2501,Nike_Sales_Uncleaned!$F$2:$F$2501>0)),Nike_Sales_Uncleaned!F5)} -> 2 | G5: {=IF(OR(Nike_Sales_Uncleaned!G5="",Nike_Sales_Uncleaned!G5<=0),MEDIAN(_xlfn._xlws.FILTER(Nike_Sales_Uncleaned!$G$2:$G$2501,Nike_Sales_Uncleaned!$G$2:$G$2501>0)),Nike_Sales_Uncleaned!G5)} -> 9673.57 | H5: =IF(Nike_Sales_Uncleaned!H5="",0,IF(AND(Nike_Sales_Uncleaned!H5>=0,Nike_Sales_Uncleaned!H5<=1),Nike_Sales_Uncleaned!H5,0)) -> 0 | I5: 0 | J5: =IF(Nike_Sales_Uncleaned[[#This Row],[Order_Date]]="","",Nike_Sales_Uncleaned[[#This Row],[Order_Date]]) -> 45569 | K5: Online | L5: Pune | M5: 3376.85
A6: 2004 | B6: Kids | C6: Running | D6: React Infinity | E6: =IF(Nike_Sales_Uncleaned!E6="","NA",IF(OR(Nike_Sales_Uncleaned!E6=0,Nike_Sales_Uncleaned!E6=-1),"NA",UPPER(Nike_Sales_Uncleaned!E6))) -> XL | F6: {=IF(Nike_Sales_Uncleaned!F6="",MEDIAN(_xlfn._xlws.FILTER(Nike_Sales_Uncleaned!$F$2:$F$2501,Nike_Sales_Uncleaned!$F$2:$F$2501>0)),Nike_Sales_Uncleaned!F6)} -> 2 | G6: {=IF(OR(Nike_Sales_Uncleaned!G6="",Nike_Sales_Uncleaned!G6<=0),MEDIAN(_xlfn._xlws.FILTER(Nike_Sales_Uncleaned!$G$2:$G$2501,Nike_Sales_Uncleaned!$G$2:$G$2501>0)),Nike_Sales_Uncleaned!G6)} -> 6110.03 | H6: =IF(Nike_Sales_Uncleaned!H6="",0,IF(AND(Nike_Sales_Uncleaned!H6>=0,Nike_Sales_Uncleaned!H6<=1),Nike_Sales_Uncleaned!H6,0)) -> 0 | I6: 0 | J6: =IF(Nike_Sales_Uncleaned[[#This Row],[Order_Date]]="","",Nike_Sales_Uncleaned[[#This Row],[Order_Date]]) -> 45547 | K6: Retail | L6: Delhi | M6: 187.89
A7: 2005 | B7: Women | C7: Training | D7: Flex Trainer | E7: =IF(Nike_Sales_Uncleaned!E7="","NA",IF(OR(Nike_Sales_Uncleaned!E7=0,Nike_Sales_Uncleaned!E7=-1),"NA",UPPER(Nike_Sales_Uncleaned!E7))) -> M | F7: {=IF(Nike_Sales_Uncleaned!F7="",MEDIAN(_xlfn._xlws.FILTER(Nike_Sales_Uncleaned!$F$2:$F$2501,Nike_Sales_Uncleaned!$F$2:$F$2501>0)),Nike_Sales_Uncleaned!F7)} -> 1 | G7: {=IF(OR(Nike_Sales_Uncleaned!G7="",Nike_Sales_Uncleaned!G7<=0),MEDIAN(_xlfn._xlws.FILTER(Nike_Sales_Uncleaned!$G$2:$G$2501,Nike_Sales_Uncleaned!$G$2:$G$2501>0)),Nike_Sales_Uncleaned!G7)} -> 7363.96 | H7: =IF(Nike_Sales_Uncleaned!H7="",0,IF(AND(Nike_Sales_Uncleaned!H7>=0,Nike_Sales_Uncleaned!H7<=1),Nike_Sales_Uncleaned!H7,0)) -> 0 | I7: 0 | J7: =IF(Nike_Sales_Uncleaned[[#This Row],[Order_Date]]="","",Nike_Sales_Uncleaned[[#This Row],[Order_Date]]) | K7: Retail | L7: Delhi | M7: 1415.98
A8: 2006 | B8: Men | C8: Training | D8: SuperRep Go | E8: =IF(Nike_Sales_Uncleaned!E8="","NA",IF(OR(Nike_Sales_Uncleaned!E8=0,Nike_Sales_Uncleaned!E8=-1),"NA",UPPER(Nike_Sales_Uncleaned!E8))) -> M | F8: {=IF(Nike_Sales_Uncleaned!F8="",MEDIAN(_xlfn._xlws.FILTER(Nike_Sales_Uncleaned!$F$2:$F$2501,Nike_Sales_Uncleaned!$F$2:$F$2501>0)),Nike_Sales_Uncleaned!F8)} -> 2 | G8: {=IF(OR(Nike_Sales_Uncleaned!G8="",Nike_Sales_Uncleaned!G8<=0),MEDIAN(_xlfn._xlws.FILTER(Nike_Sales_Uncleaned!$G$2:$G$2501,Nike_Sales_Uncleaned!$G$2:$G$2501>0)),Nike_Sales_Uncleaned!G8)} -> 6819.78 | H8: =IF(Nike_Sales_Uncleaned!H8="",0,IF(AND(Nike_Sales_Uncleaned!H8>=0,Nike_Sales_Uncleaned!H8<=1),Nike_Sales_Uncleaned!H8,0)) -> 0 | I8: 0 | J8: =IF(Nike_Sales_Uncleaned[[#This Row],[Order_Date]]="","",Nike_Sales_Uncleaned[[#This Row],[Order_Date]]) -> 45812 | K8: Online | L8: Bangalore | M8: 1802.09
A9: 2007 | B9: Kids | C9: Training | D9: SuperRep Go | E9: =IF(Nike_Sales_Uncleaned!E9="","NA",IF(OR(Nike_Sales_Uncleaned!E9=0,Nike_Sales_Uncleaned!E9=-1),"NA",UPPER(Nike_Sales_Uncleaned!E9))) -> M | F9: {=IF(Nike_Sales_Uncleaned!F9="",MEDIAN(_xlfn._xlws.FILTER(Nike_Sales_Uncleaned!$F$2:$F$2501,Nike_Sales_Uncleaned!$F$2:$F$2501>0)),Nike_Sales_Uncleaned!F9)} -> 1 | G9: {=IF(OR(Nike_Sales_Uncleaned!G9="",Nike_Sales_Uncleaned!G9<=0),MEDIAN(_xlfn._xlws.FILTER(Nike_Sales_Uncleaned!$G$2:$G$2501,Nike_Sales_Uncleaned!$G$2:$G$2501>0)),Nike_Sales_Uncleaned!G9)} -> 6110.03 | H9: =IF(Nike_Sales_Uncleaned!H9="",0,IF(AND(Nike_Sales_Uncleaned!H9>=0,Nike_Sales_Uncleaned!H9<=1),Nike_Sales_Uncleaned!H9,0)) -> 0.32 | I9: 0 | J9: =IF(Nike_Sales_Uncleaned[[#This Row],[Order_Date]]="","",Nike_Sales_Uncleaned[[#This Row],[Order_Date]]) | K9: Retail | L9: Bangalore | M9: 2928.36
A10: 2008 | B10: Women | C10: Soccer | D10: Premier III | E10: =IF(Nike_Sales_Uncleaned!E10="","NA",IF(OR(Nike_Sales_Uncleaned!E10=0,Nike_Sales_Uncleaned!E10=-1),"NA",UPPER(Nike_Sales_Uncleaned!E10))) -> 11 | F10: {=IF(Nike_Sales_Uncleaned!F10="",MEDIAN(_xlfn._xlws.FILTER(Nike_Sales_Uncleaned!$F$2:$F$2501,Nike_Sales_Uncleaned!$F$2:$F$2501>0)),Nike_Sales_Uncleaned!F10)} -> -1 | G10: {=IF(OR(Nike_Sales_Uncleaned!G10="",Nike_Sales_Uncleaned!G10<=0),MEDIAN(_xlfn._xlws.FILTER(Nike_Sales_Uncleaned!$G$2:$G$2501,Nike_Sales_Uncleaned!$G$2:$G$2501>0)),Nike_Sales_Uncleaned!G10)} -> 6110.03 | H10: =IF(Nike_Sales_Uncleaned!H10="",0,IF(AND(Nike_Sales_Uncleaned!H10>=0,Nike_Sales_Uncleaned!H10<=1),Nike_Sales_Uncleaned!H10,0)) -> 0 | I10: 0 | J10: =IF(Nike_Sales_Uncleaned[[#This Row],[Order_Date]]="","",Nike_Sales_Uncleaned[[#This Row],[Order_Date]]) -> 45576 | K10: Online | L10: Hyderabad | M10: -731.18
A11: 2009 | B11: Men | C11: Soccer | D11: Mercurial Superfly | E11: =IF(Nike_Sales_Uncleaned!E11="","NA",IF(OR(Nike_Sales_Uncleaned!E11=0,Nike_Sales_Uncleaned!E11=-1),"NA",UPPER(Nike_Sales_Uncleaned!E11))) -> M | F11: {=IF(Nike_Sales_Uncleaned!F11="",MEDIAN(_xlfn._xlws.FILTER(Nike_Sales_Uncleaned!$F$2:$F$2501,Nike_Sales_Uncleaned!$F$2:$F$2501>0)),Nike_Sales_Uncleaned!F11)} -> 4 | G11: {=IF(OR(Nike_Sales_Uncleaned!G11="",Nike_Sales_Uncleaned!G11<=0),MEDIAN(_xlfn._xlws.FILTER(Nike_Sales_Uncleaned!$G$2:$G$2501,Nike_Sales_Uncleaned!$G$2:$G$2501>0)),Nike_Sales_Uncleaned!G11)} -> 6110.03 | H11: =IF(Nike_Sales_Uncleaned!H11="",0,IF(AND(Nike_Sales_Uncleaned!H11>=0,Nike_Sales_Uncleaned!H11<=1),Nike_Sales_Uncleaned!H11,0)) -> 0 | I11: 0 | J11: =IF(Nike_Sales_Uncleaned[[#This Row],[Order_Date]]="","",Nike_Sales_Uncleaned[[#This Row],[Order_Date]]) | K11: Online | L11: Pune | M11: 3929.61
A12: 2010 | B12: Kids | C12: Lifestyle | D12: Waffle One | E12: =IF(Nike_Sales_Uncleaned!E12="","NA",IF(OR(Nike_Sales_Uncleaned!E12=0,Nike_Sales_Uncleaned!E12=-1),"NA",UPPER(Nike_Sales_Uncleaned!E12))) -> L | F12: {=IF(Nike_Sales_Uncleaned!F12="",MEDIAN(_xlfn._xlws.FILTER(Nike_Sales_Uncleaned!$F$2:$F$2501,Nike_Sales_Uncleaned!$F$2:$F$2501>0)),Nike_Sales_Uncleaned!F12)} -> 1 | G12: {=IF(OR(Nike_Sales_Uncleaned!G12="",Nike_Sales_Uncleaned!G12<=0),MEDIAN(_xlfn._xlws.FILTER(Nike_Sales_Uncleaned!$G$2:$G$2501,Nike_Sales_Uncleaned!$G$2:$G$2501>0)),Nike_Sales_Uncleaned!G12)} -> 7949.83 | H12: =IF(Nike_Sales_Uncleaned!H12="",0,IF(AND(Nike_Sales_Uncleaned!H12>=0,Nike_Sales_Uncleaned!H12<=1),Nike_Sales_Uncleaned!H12,0)) -> 0 | I12: 0 | J12: =IF(Nike_Sales_Uncleaned[[#This Row],[Order_Date]]="","",Nike_Sales_Uncleaned[[#This Row],[Order_Date]]) -> 45673 | K12: Online | L12: Pune | M12: 1965.56
A13: 2011 | B13: Women | C13: Training | D13: Flex Trainer | E13: =IF(Nike_Sales_Uncleaned!E13="","NA",IF(OR(Nike_Sales_Uncleaned!E13=0,Nike_Sales_Uncleaned!E13=-1),"NA",UPPER(Nike_Sales_Uncleaned!E13))) -> L | F13: {=IF(Nike_Sales_Uncleaned!F13="",MEDIAN(_xlfn._xlws.FILTER(Nike_Sales_Uncleaned!$F$2:$F$2501,Nike_Sales_Uncleaned!$F$2:$F$2501>0)),Nike_Sales_Uncleaned!F13)} -> -1 | G13: {=IF(OR(Nike_Sales_Uncleaned!G13="",Nike_Sales_Uncleaned!G13<=0),MEDIAN(_xlfn._xlws.FILTER(Nike_Sales_Uncleaned!$G$2:$G$2501,Nike_Sales_Uncleaned!$G$2:$G$2501>0)),Nike_Sales_Uncleaned!G13)} -> 9586.08 | H13: =IF(Nike_Sales_Uncleaned!H13="",0,IF(AND(Nike_Sales_Uncleaned!H13>=0,Nike_Sales_Uncleaned!H13<=1),Nike_Sales_Uncleaned!H13,0)) -> 0 | I13: 0 | J13: =IF(Nike_Sales_Uncleaned[[#This Row],[Order_Date]]="","",Nike_Sales_Uncleaned[[#This Row],[Order_Date]]) | K13: Retail | L13: Hyderabad | M13: 1667.08
... A19: 2017 | B19: Women | C19: Basketball | D19: Air Jordan | E19: =IF(Nike_Sales_Uncleaned!E19="","NA",IF(OR(Nike_Sales_Uncleaned!E19=0,Nike_Sales_Uncleaned!E19=-1),"NA",UPPER(Nike_Sales_Uncleaned!E19))) -> 9 | F19: {=IF(Nike_Sales_Uncleaned!F19="",MEDIAN(_xlfn._xlws.FILTER(Nike_Sales_Uncleaned!$F$2:$F$2501,Nike_Sales_Uncleaned!$F$2:$F$2501>0)),Nike_Sales_Uncleaned!F19)} -> 4 | G19: {=IF(OR(Nike_Sales_Uncleaned!G19="",Nike_Sales_Uncleaned!G19<=0),MEDIAN(_xlfn._xlws.FILTER(Nike_Sales_Uncleaned!$G$2:$G$2501,Nike_Sales_Uncleaned!$G$2:$G$2501>0)),Nike_Sales_Uncleaned!G19)} -> 6110.03 | H19: =IF(Nike_Sales_Uncleaned!H19="",0,IF(AND(Nike_Sales_Uncleaned!H19>=0,Nike_Sales_Uncleaned!H19<=1),Nike_Sales_Uncleaned!H19,0)) -> 0 | I19: 0 | J19: =IF(Nike_Sales_Uncleaned[[#This Row],[Order_Date]]="","",Nike_Sales_Uncleaned[[#This Row],[Order_Date]]) -> 45733 | K19: Retail | L19: Delhi | M19: 1946.24
A20: 2019 | B20: Kids | C20: Running | D20: Air Zoom | E20: =IF(Nike_Sales_Uncleaned!E21="","NA",IF(OR(Nike_Sales_Uncleaned!E21=0,Nike_Sales_Uncleaned!E21=-1),"NA",UPPER(Nike_Sales_Uncleaned!E21))) -> 6 | F20: {=IF(Nike_Sales_Uncleaned!F21="",MEDIAN(_xlfn._xlws.FILTER(Nike_Sales_Uncleaned!$F$2:$F$2501,Nike_Sales_Uncleaned!$F$2:$F$2501>0)),Nike_Sales_Uncleaned!F21)} -> 0 | G20: {=IF(OR(Nike_Sales_Uncleaned!G21="",Nike_Sales_Uncleaned!G21<=0),MEDIAN(_xlfn._xlws.FILTER(Nike_Sales_Uncleaned!$G$2:$G$2501,Nike_Sales_Uncleaned!$G$2:$G$2501>0)),Nike_Sales_Uncleaned!G21)} -> 3424.06 | H20: =IF(Nike_Sales_Uncleaned!H21="",0,IF(AND(Nike_Sales_Uncleaned!H21>=0,Nike_Sales_Uncleaned!H21<=1),Nike_Sales_Uncleaned!H21,0)) -> 0.32 | I20: 0 | J20: =IF(Nike_Sales_Uncleaned[[#This Row],[Order_Date]]="","",Nike_Sales_Uncleaned[[#This Row],[Order_Date]]) | K20: Online | L20: Hyderabad | M20: 1915.24
A21: 2020 | B21: Kids | C21: Soccer | D21: Tiempo Legend | E21: =IF(Nike_Sales_Uncleaned!E22="","NA",IF(OR(Nike_Sales_Uncleaned!E22=0,Nike_Sales_Uncleaned!E22=-1),"NA",UPPER(Nike_Sales_Uncleaned!E22))) -> L | F21: {=IF(Nike_Sales_Uncleaned!F22="",MEDIAN(_xlfn._xlws.FILTER(Nike_Sales_Uncleaned!$F$2:$F$2501,Nike_Sales_Uncleaned!$F$2:$F$2501>0)),Nike_Sales_Uncleaned!F22)} -> -1 | G21: {=IF(OR(Nike_Sales_Uncleaned!G22="",Nike_Sales_Uncleaned!G22<=0),MEDIAN(_xlfn._xlws.FILTER(Nike_Sales_Uncleaned!$G$2:$G$2501,Nike_Sales_Uncleaned!$G$2:$G$2501>0)),Nike_Sales_Uncleaned!G22)} -> 6110.03 | H21: =IF(Nike_Sales_Uncleaned!H22="",0,IF(AND(Nike_Sales_Uncleaned!H22>=0,Nike_Sales_Uncleaned!H22<=1),Nike_Sales_Uncleaned!H22,0)) -> 0.67 | I21: 0 | J21: =IF(Nike_Sales_Uncleaned[[#This Row],[Order_Date]]="","",Nike_Sales_Uncleaned[[#This Row],[Order_Date]]) -> 45674 | K21: Retail | L21: Mumbai | M21: 439.96
A22: 2021 | B22: Men | C22: Running | D22: Free RN | E22: =IF(Nike_Sales_Uncleaned!E23="","NA",IF(OR(Nike_Sales_Uncleaned!E23=0,Nike_Sales_Uncleaned!E23=-1),"NA",UPPER(Nike_Sales_Uncleaned!E23))) -> L | F22: {=IF(Nike_Sales_Uncleaned!F23="",MEDIAN(_xlfn._xlws.FILTER(Nike_Sales_Uncleaned!$F$2:$F$2501,Nike_Sales_Uncleaned!$F$2:$F$2501>0)),Nike_Sales_Uncleaned!F23)} -> -1 | G22: {=IF(OR(Nike_Sales_Uncleaned!G23="",Nike_Sales_Uncleaned!G23<=0),MEDIAN(_xlfn._xlws.FILTER(Nike_Sales_Uncleaned!$G$2:$G$2501,Nike_Sales_Uncleaned!$G$2:$G$2501>0)),Nike_Sales_Uncleaned!G23)} -> 7086.7 | H22: =IF(Nike_Sales_Uncleaned!H23="",0,IF(AND(Nike_Sales_Uncleaned!H23>=0,Nike_Sales_Uncleaned!H23<=1),Nike_Sales_Uncleaned!H23,0)) -> 0.66 | I22: -2409.48 | J22: =IF(Nike_Sales_Uncleaned[[#This Row],[Order_Date]]="","",Nike_Sales_Uncleaned[[#This Row],[Order_Date]]) -> 45744 | K22: Retail | L22: Hyderabad | M22: -1120.49
A23: 2022 | B23: Women | C23: Soccer | D23: Premier III | E23: =IF(Nike_Sales_Uncleaned!E24="","NA",IF(OR(Nike_Sales_Uncleaned!E24=0,Nike_Sales_Uncleaned!E24=-1),"NA",UPPER(Nike_Sales_Uncleaned!E24))) -> M | F23: {=IF(Nike_Sales_Uncleaned!F24="",MEDIAN(_xlfn._xlws.FILTER(Nike_Sales_Uncleaned!$F$2:$F$2501,Nike_Sales_Uncleaned!$F$2:$F$2501>0)),Nike_Sales_Uncleaned!F24)} -> 2 | G23: {=IF(OR(Nike_Sales_Uncleaned!G24="",Nike_Sales_Uncleaned!G24<=0),MEDIAN(_xlfn._xlws.FILTER(Nike_Sales_Uncleaned!$G$2:$G$2501,Nike_Sales_Uncleaned!$G$2:$G$2501>0)),Nike_Sales_Uncleaned!G24)} -> 6110.03 | H23: =IF(Nike_Sales_Uncleaned!H24="",0,IF(AND(Nike_Sales_Uncleaned!H24>=0,Nike_Sales_Uncleaned!H24<=1),Nike_Sales_Uncleaned!H24,0)) -> 0 | I23: 0 | J23: =IF(Nike_Sales_Uncleaned[[#This Row],[Order_Date]]="","",Nike_Sales_Uncleaned[[#This Row],[Order_Date]]) -> 45615 | K23: Online | L23: Pune | M23: 3427.16
A24: 2023 | B24: Men | C24: Lifestyle | D24: Waffle One | E24: =IF(Nike_Sales_Uncleaned!E25="","NA",IF(OR(Nike_Sales_Uncleaned!E25=0,Nike_Sales_Uncleaned!E25=-1),"NA",UPPER(Nike_Sales_Uncleaned!E25))) -> M | F24: {=IF(Nike_Sales_Uncleaned!F25="",MEDIAN(_xlfn._xlws.FILTER(Nike_Sales_Uncleaned!$F$2:$F$2501,Nike_Sales_Uncleaned!$F$2:$F$2501>0)),Nike_Sales_Uncleaned!F25)} -> 2 | G24: {=IF(OR(Nike_Sales_Uncleaned!G25="",Nike_Sales_Uncleaned!G25<=0),MEDIAN(_xlfn._xlws.FILTER(Nike_Sales_Uncleaned!$G$2:$G$2501,Nike_Sales_Uncleaned!$G$2:$G$2501>0)),Nike_Sales_Uncleaned!G25)} -> 5003.95 | H24: =IF(Nike_Sales_Uncleaned!H25="",0,IF(AND(Nike_Sales_Uncleaned!H25>=0,Nike_Sales_Uncleaned!H25<=1),Nike_Sales_Uncleaned!H25,0)) -> 0 | I24: 0 | J24: =IF(Nike_Sales_Uncleaned[[#This Row],[Order_Date]]="","",Nike_Sales_Uncleaned[[#This Row],[Order_Date]]) -> 45559 | K24: Online | L24: Mumbai | M24: 1498.37
A25: 2024 | B25: Kids | C25: Training | D25: SuperRep Go | E25: =IF(Nike_Sales_Uncleaned!E26="","NA",IF(OR(Nike_Sales_Uncleaned!E26=0,Nike_Sales_Uncleaned!E26=-1),"NA",UPPER(Nike_Sales_Uncleaned!E26))) -> XL | F25: {=IF(Nike_Sales_Uncleaned!F26="",MEDIAN(_xlfn._xlws.FILTER(Nike_Sales_Uncleaned!$F$2:$F$2501,Nike_Sales_Uncleaned!$F$2:$F$2501>0)),Nike_Sales_Uncleaned!F26)} -> 0 | G25: {=IF(OR(Nike_Sales_Uncleaned!G26="",Nike_Sales_Uncleaned!G26<=0),MEDIAN(_xlfn._xlws.FILTER(Nike_Sales_Uncleaned!$G$2:$G$2501,Nike_Sales_Uncleaned!$G$2:$G$2501>0)),Nike_Sales_Uncleaned!G26)} -> 6110.03 | H25: =IF(Nike_Sales_Uncleaned!H26="",0,IF(AND(Nike_Sales_Uncleaned!H26>=0,Nike_Sales_Uncleaned!H26<=1),Nike_Sales_Uncleaned!H26,0)) -> 0.5 | I25: 0 | J25: =IF(Nike_Sales_Uncleaned[[#This Row],[Order_Date]]="","",Nike_Sales_Uncleaned[[#This Row],[Order_Date]]) -> 45667 | K25: Retail | L25: Bangalore | M25: 1842.35
A26: 2025 | B26: Women | C26: Basketball | D26: Kyrie Flytrap | E26: =IF(Nike_Sales_Uncleaned!E27="","NA",IF(OR(Nike_Sales_Uncleaned!E27=0,Nike_Sales_Uncleaned!E27=-1),"NA",UPPER(Nike_Sales_Uncleaned!E27))) -> M | F26: {=IF(Nike_Sales_Uncleaned!F27="",MEDIAN(_xlfn._xlws.FILTER(Nike_Sales_Uncleaned!$F$2:$F$2501,Nike_Sales_Uncleaned!$F$2:$F$2501>0)),Nike_Sales_Uncleaned!F27)} -> 3 | G26: {=IF(OR(Nike_Sales_Uncleaned!G27="",Nike_Sales_Uncleaned!G27<=0),MEDIAN(_xlfn._xlws.FILTER(Nike_Sales_Uncleaned!$G$2:$G$2501,Nike_Sales_Uncleaned!$G$2:$G$2501>0)),Nike_Sales_Uncleaned!G27)} -> 9820.5 | H26: =IF(Nike_Sales_Uncleaned!H27="",0,IF(AND(Nike_Sales_Uncleaned!H27>=0,Nike_Sales_Uncleaned!H27<=1),Nike_Sales_Uncleaned!H27,0)) -> 0 | I26: 0 | J26: =IF(Nike_Sales_Uncleaned[[#This Row],[Order_Date]]="","",Nike_Sales_Uncleaned[[#This Row],[Order_Date]]) -> 45654 | K26: Retail | L26: Mumbai | M26: 1900.15
A27: 2026 | B27: Kids | C27: Lifestyle | D27: Blazer Mid | E27: =IF(Nike_Sales_Uncleaned!E28="","NA",IF(OR(Nike_Sales_Uncleaned!E28=0,Nike_Sales_Uncleaned!E28=-1),"NA",UPPER(Nike_Sales_Uncleaned!E28))) -> XL | F27: {=IF(Nike_Sales_Uncleaned!F28="",MEDIAN(_xlfn._xlws.FILTER(Nike_Sales_Uncleaned!$F$2:$F$2501,Nike_Sales_Uncleaned!$F$2:$F$2501>0)),Nike_Sales_Uncleaned!F28)} -> 1 | G27: {=IF(OR(Nike_Sales_Uncleaned!G28="",Nike_Sales_Uncleaned!G28<=0),MEDIAN(_xlfn._xlws.FILTER(Nike_Sales_Uncleaned!$G$2:$G$2501,Nike_Sales_Uncleaned!$G$2:$G$2501>0)),Nike_Sales_Uncleaned!G28)} -> 6110.03 | H27: =IF(Nike_Sales_Uncleaned!H28="",0,IF(AND(Nike_Sales_Uncleaned!H28>=0,Nike_Sales_Uncleaned!H28<=1),Nike_Sales_Uncleaned!H28,0)) -> 0.16 | I27: 0 | J27: =IF(Nike_Sales_Uncleaned[[#This Row],[Order_Date]]="","",Nike_Sales_Uncleaned[[#This Row],[Order_Date]]) | K27: Retail | L27: Kolkata | M27: 2301.64
A28: 2027 | B28: Men | C28: Basketball | D28: Zoom Freak | E28: =IF(Nike_Sales_Uncleaned!E29="","NA",IF(OR(Nike_Sales_Uncleaned!E29=0,Nike_Sales_Uncleaned!E29=-1),"NA",UPPER(Nike_Sales_Uncleaned!E29))) -> XL | F28: {=IF(Nike_Sales_Uncleaned!F29="",MEDIAN(_xlfn._xlws.FILTER(Nike_Sales_Uncleaned!$F$2:$F$2501,Nike_Sales_Uncleaned!$F$2:$F$2501>0)),Nike_Sales_Uncleaned!F29)} -> 2 | G28: {=IF(OR(Nike_Sales_Uncleaned!G29="",Nike_Sales_Uncleaned!G29<=0),MEDIAN(_xlfn._xlws.FILTER(Nike_Sales_Uncleaned!$G$2:$G$2501,Nike_Sales_Uncleaned!$G$2:$G$2501>0)),Nike_Sales_Uncleaned!G29)} -> 6110.03 | H28: =IF(Nike_Sales_Uncleaned!H29="",0,IF(AND(Nike_Sales_Uncleaned!H29>=0,Nike_Sales_Uncleaned!H29<=1),Nike_Sales_Uncleaned!H29,0)) -> 0.22 | I28: 0 | J28: =IF(Nike_Sales_Uncleaned[[#This Row],[Order_Date]]="","",Nike_Sales_Uncleaned[[#This Row],[Order_Date]]) -> 45514 | K28: Online | L28: Pune | M28: -138.74
A29: 2028 | B29: Men | C29: Training | D29: Flex Trainer | E29: =IF(Nike_Sales_Uncleaned!E30="","NA",IF(OR(Nike_Sales_Uncleaned!E30=0,Nike_Sales_Uncleaned!E30=-1),"NA",UPPER(Nike_Sales_Uncleaned!E30))) -> 12 | F29: {=IF(Nike_Sales_Uncleaned!F30="",MEDIAN(_xlfn._xlws.FILTER(Nike_Sales_Uncleaned!$F$2:$F$2501,Nike_Sales_Uncleaned!$F$2:$F$2501>0)),Nike_Sales_Uncleaned!F30)} -> 2 | G29: {=IF(OR(Nike_Sales_Uncleaned!G30="",Nike_Sales_Uncleaned!G30<=0),MEDIAN(_xlfn._xlws.FILTER(Nike_Sales_Uncleaned!$G$2:$G$2501,Nike_Sales_Uncleaned!$G$2:$G$2501>0)),Nike_Sales_Uncleaned!G30)} -> 3270.23 | H29: =IF(Nike_Sales_Uncleaned!H30="",0,IF(AND(Nike_Sales_Uncleaned!H30>=0,Nike_Sales_Uncleaned!H30<=1),Nike_Sales_Uncleaned!H30,0)) -> 0 | I29: 0 | J29: =IF(Nike_Sales_Uncleaned[[#This Row],[Order_Date]]="","",Nike_Sales_Uncleaned[[#This Row],[Order_Date]]) | K29: Retail | L29: Delhi | M29: -946.86
A30: 2029 | B30: Men | C30: Training | D30: ZoomX Invincible | E30: =IF(Nike_Sales_Uncleaned!E31="","NA",IF(OR(Nike_Sales_Uncleaned!E31=0,Nike_Sales_Uncleaned!E31=-1),"NA",UPPER(Nike_Sales_Uncleaned!E31))) -> 12 | F30: {=IF(Nike_Sales_Uncleaned!F31="",MEDIAN(_xlfn._xlws.FILTER(Nike_Sales_Uncleaned!$F$2:$F$2501,Nike_Sales_Uncleaned!$F$2:$F$2501>0)),Nike_Sales_Uncleaned!F31)} -> 0 | G30: {=IF(OR(Nike_Sales_Uncleaned!G31="",Nike_Sales_Uncleaned!G31<=0),MEDIAN(_xlfn._xlws.FILTER(Nike_Sales_Uncleaned!$G$2:$G$2501,Nike_Sales_Uncleaned!$G$2:$G$2501>0)),Nike_Sales_Uncleaned!G31)} -> 6110.03 | H30: =IF(Nike_Sales_Uncleaned!H31="",0,IF(AND(Nike_Sales_Uncleaned!H31>=0,Nike_Sales_Uncleaned!H31<=1),Nike_Sales_Uncleaned!H31,0)) -> 0 | I30: 0 | J30: =IF(Nike_Sales_Uncleaned[[#This Row],[Order_Date]]="","",Nike_Sales_Uncleaned[[#This Row],[Order_Date]]) | K30: Online | L30: Bangalore | M30: -185.67
A31: 2030 | B31: Men | C31: Soccer | D31: Phantom GT | E31: =IF(Nike_Sales_Uncleaned!E32="","NA",IF(OR(Nike_Sales_Uncleaned!E32=0,Nike_Sales_Uncleaned!E32=-1),"NA",UPPER(Nike_Sales_Uncleaned!E32))) -> XL | F31: {=IF(Nike_Sales_Uncleaned!F32="",MEDIAN(_xlfn._xlws.FILTER(Nike_Sales_Uncleaned!$F$2:$F$2501,Nike_Sales_Uncleaned!$F$2:$F$2501>0)),Nike_Sales_Uncleaned!F32)} -> 2 | G31: {=IF(OR(Nike_Sales_Uncleaned!G32="",Nike_Sales_Uncleaned!G32<=0),MEDIAN(_xlfn._xlws.FILTER(Nike_Sales_Uncleaned!$G$2:$G$2501,Nike_Sales_Uncleaned!$G$2:$G$2501>0)),Nike_Sales_Uncleaned!G32)} -> 6110.03 | H31: =IF(Nike_Sales_Uncleaned!H32="",0,IF(AND(Nike_Sales_Uncleaned!H32>=0,Nike_Sales_Uncleaned!H32<=1),Nike_Sales_Uncleaned!H32,0)) -> 0 | I31: 0 | J31: =IF(Nike_Sales_Uncleaned[[#This Row],[Order_Date]]="","",Nike_Sales_Uncleaned[[#This Row],[Order_Date]]) -> 45227 | K31: Retail | L31: Hyderabad | M31: -122.93
... A40: 2039 | B40: Women | C40: Training | D40: Flex Trainer | E40: =IF(Nike_Sales_Uncleaned!E41="","NA",IF(OR(Nike_Sales_Uncleaned!E41=0,Nike_Sales_Uncleaned!E41=-1),"NA",UPPER(Nike_Sales_Uncleaned!E41))) -> M | F40: {=IF(Nike_Sales_Uncleaned!F41="",MEDIAN(_xlfn._xlws.FILTER(Nike_Sales_Uncleaned!$F$2:$F$2501,Nike_Sales_Uncleaned!$F$2:$F$2501>0)),Nike_Sales_Uncleaned!F41)} -> 2 | G40: {=IF(OR(Nike_Sales_Uncleaned!G41="",Nike_Sales_Uncleaned!G41<=0),MEDIAN(_xlfn._xlws.FILTER(Nike_Sales_Uncleaned!$G$2:$G$2501,Nike_Sales_Uncleaned!$G$2:$G$2501>0)),Nike_Sales_Uncleaned!G41)} -> 2767.7 | H40: =IF(Nike_Sales_Uncleaned!H41="",0,IF(AND(Nike_Sales_Uncleaned!H41>=0,Nike_Sales_Uncleaned!H41<=1),Nike_Sales_Uncleaned!H41,0)) -> 0.63 | I40: 0 | J40: =IF(Nike_Sales_Uncleaned[[#This Row],[Order_Date]]="","",Nike_Sales_Uncleaned[[#This Row],[Order_Date]]) | K40: Retail | L40: Hyderabad | M40: -336.3
A41: 2041 | B41: Kids | C41: Soccer | D41: Tiempo Legend | E41: =IF(Nike_Sales_Uncleaned!E43="","NA",IF(OR(Nike_Sales_Uncleaned!E43=0,Nike_Sales_Uncleaned!E43=-1),"NA",UPPER(Nike_Sales_Uncleaned!E43))) -> 12 | F41: {=IF(Nike_Sales_Uncleaned!F43="",MEDIAN(_xlfn._xlws.FILTER(Nike_Sales_Uncleaned!$F$2:$F$2501,Nike_Sales_Uncleaned!$F$2:$F$2501>0)),Nike_Sales_Uncleaned!F43)} -> 2 | G41: {=IF(OR(Nike_Sales_Uncleaned!G43="",Nike_Sales_Uncleaned!G43<=0),MEDIAN(_xlfn._xlws.FILTER(Nike_Sales_Uncleaned!$G$2:$G$2501,Nike_Sales_Uncleaned!$G$2:$G$2501>0)),Nike_Sales_Uncleaned!G43)} -> 5553.88 | H41: =IF(Nike_Sales_Uncleaned!H43="",0,IF(AND(Nike_Sales_Uncleaned!H43>=0,Nike_Sales_Uncleaned!H43<=1),Nike_Sales_Uncleaned!H43,0)) -> 0 | I41: 0 | J41: =IF(Nike_Sales_Uncleaned[[#This Row],[Order_Date]]="","",Nike_Sales_Uncleaned[[#This Row],[Order_Date]]) -> 45769 | K41: Online | L41: Hyderabad | M41: 2371.66
A42: 2042 | B42: Women | C42: Basketball | D42: Kyrie Flytrap | E42: =IF(Nike_Sales_Uncleaned!E44="","NA",IF(OR(Nike_Sales_Uncleaned!E44=0,Nike_Sales_Uncleaned!E44=-1),"NA",UPPER(Nike_Sales_Uncleaned!E44))) -> L | F42: {=IF(Nike_Sales_Uncleaned!F44="",MEDIAN(_xlfn._xlws.FILTER(Nike_Sales_Uncleaned!$F$2:$F$2501,Nike_Sales_Uncleaned!$F$2:$F$2501>0)),Nike_Sales_Uncleaned!F44)} -> 2 | G42: {=IF(OR(Nike_Sales_Uncleaned!G44="",Nike_Sales_Uncleaned!G44<=0),MEDIAN(_xlfn._xlws.FILTER(Nike_Sales_Uncleaned!$G$2:$G$2501,Nike_Sales_Uncleaned!$G$2:$G$2501>0)),Nike_Sales_Uncleaned!G44)} -> 6110.03 | H42: =IF(Nike_Sales_Uncleaned!H44="",0,IF(AND(Nike_Sales_Uncleaned!H44>=0,Nike_Sales_Uncleaned!H44<=1),Nike_Sales_Uncleaned!H44,0)) -> 0 | I42: 0 | J42: =IF(Nike_Sales_Uncleaned[[#This Row],[Order_Date]]="","",Nike_Sales_Uncleaned[[#This Row],[Order_Date]]) -> 45723 | K42: Online | L42: Hyderabad | M42: -862.16
A43: 2043 | B43: Men | C43: Soccer | D43: Premier III | E43: =IF(Nike_Sales_Uncleaned!E45="","NA",IF(OR(Nike_Sales_Uncleaned!E45=0,Nike_Sales_Uncleaned!E45=-1),"NA",UPPER(Nike_Sales_Uncleaned!E45))) -> XL | F43: {=IF(Nike_Sales_Uncleaned!F45="",MEDIAN(_xlfn._xlws.FILTER(Nike_Sales_Uncleaned!$F$2:$F$2501,Nike_Sales_Uncleaned!$F$2:$F$2501>0)),Nike_Sales_Uncleaned!F45)} -> 2 | G43: {=IF(OR(Nike_Sales_Uncleaned!G45="",Nike_Sales_Uncleaned!G45<=0),MEDIAN(_xlfn._xlws.FILTER(Nike_Sales_Uncleaned!$G$2:$G$2501,Nike_Sales_Uncleaned!$G$2:$G$2501>0)),Nike_Sales_Uncleaned!G45)} -> 3492.89 | H43: =IF(Nike_Sales_Uncleaned!H45="",0,IF(AND(Nike_Sales_Uncleaned!H45>=0,Nike_Sales_Uncleaned!H45<=1),Nike_Sales_Uncleaned!H45,0)) -> 0.77 | I43: 0 | J43: =IF(Nike_Sales_Uncleaned[[#This Row],[Order_Date]]="","",Nike_Sales_Uncleaned[[#This Row],[Order_Date]]) -> 45721 | K43: Retail | L43: Delhi | M43: 3770.75
A44: 2044 | B44: Kids | C44: Training | D44: SuperRep Go | E44: =IF(Nike_Sales_Uncleaned!E46="","NA",IF(OR(Nike_Sales_Uncleaned!E46=0,Nike_Sales_Uncleaned!E46=-1),"NA",UPPER(Nike_Sales_Uncleaned!E46))) -> NA | F44: {=IF(Nike_Sales_Uncleaned!F46="",MEDIAN(_xlfn._xlws.FILTER(Nike_Sales_Uncleaned!$F$2:$F$2501,Nike_Sales_Uncleaned!$F$2:$F$2501>0)),Nike_Sales_Uncleaned!F46)} -> 2 | G44: {=IF(OR(Nike_Sales_Uncleaned!G46="",Nike_Sales_Uncleaned!G46<=0),MEDIAN(_xlfn._xlws.FILTER(Nike_Sales_Uncleaned!$G$2:$G$2501,Nike_Sales_Uncleaned!$G$2:$G$2501>0)),Nike_Sales_Uncleaned!G46)} -> 6110.03 | H44: =IF(Nike_Sales_Uncleaned!H46="",0,IF(AND(Nike_Sales_Uncleaned!H46>=0,Nike_Sales_Uncleaned!H46<=1),Nike_Sales_Uncleaned!H46,0)) -> 0 | I44: 0 | J44: =IF(Nike_Sales_Uncleaned[[#This Row],[Order_Date]]="","",Nike_Sales_Uncleaned[[#This Row],[Order_Date]]) -> 45766 | K44: Online | L44: Delhi | M44: 2174.71
A45: 2045 | B45: Kids | C45: Lifestyle | D45: Dunk Low | E45: =IF(Nike_Sales_Uncleaned!E47="","NA",IF(OR(Nike_Sales_Uncleaned!E47=0,Nike_Sales_Uncleaned!E47=-1),"NA",UPPER(Nike_Sales_Uncleaned!E47))) -> XL | F45: {=IF(Nike_Sales_Uncleaned!F47="",MEDIAN(_xlfn._xlws.FILTER(Nike_Sales_Uncleaned!$F$2:$F$2501,Nike_Sales_Uncleaned!$F$2:$F$2501>0)),Nike_Sales_Uncleaned!F47)} -> 4 | G45: {=IF(OR(Nike_Sales_Uncleaned!G47="",Nike_Sales_Uncleaned!G47<=0),MEDIAN(_xlfn._xlws.FILTER(Nike_Sales_Uncleaned!$G$2:$G$2501,Nike_Sales_Uncleaned!$G$2:$G$2501>0)),Nike_Sales_Uncleaned!G47)} -> 6110.03 | H45: =IF(Nike_Sales_Uncleaned!H47="",0,IF(AND(Nike_Sales_Uncleaned!H47>=0,Nike_Sales_Uncleaned!H47<=1),Nike_Sales_Uncleaned!H47,0)) -> 0 | I45: 0 | J45: =IF(Nike_Sales_Uncleaned[[#This Row],[Order_Date]]="","",Nike_Sales_Uncleaned[[#This Row],[Order_Date]]) -> 45414 | K45: Retail | L45: Delhi | M45: 1833.94
A46: 2046 | B46: Kids | C46: Running | D46: Air Zoom | E46: =IF(Nike_Sales_Uncleaned!E48="","NA",IF(OR(Nike_Sales_Uncleaned!E48=0,Nike_Sales_Uncleaned!E48=-1),"NA",UPPER(Nike_Sales_Uncleaned!E48))) -> 12 | F46: {=IF(Nike_Sales_Uncleaned!F48="",MEDIAN(_xlfn._xlws.FILTER(Nike_Sales_Uncleaned!$F$2:$F$2501,Nike_Sales_Uncleaned!$F$2:$F$2501>0)),Nike_Sales_Uncleaned!F48)} -> 2 | G46: {=IF(OR(Nike_Sales_Uncleaned!G48="",Nike_Sales_Uncleaned!G48<=0),MEDIAN(_xlfn._xlws.FILTER(Nike_Sales_Uncleaned!$G$2:$G$2501,Nike_Sales_Uncleaned!$G$2:$G$2501>0)),Nike_Sales_Uncleaned!G48)} -> 6110.03 | H46: =IF(Nike_Sales_Uncleaned!H48="",0,IF(AND(Nike_Sales_Uncleaned!H48>=0,Nike_Sales_Uncleaned!H48<=1),Nike_Sales_Uncleaned!H48,0)) -> 0 | I46: 0 | J46: =IF(Nike_Sales_Uncleaned[[#This Row],[Order_Date]]="","",Nike_Sales_Uncleaned[[#This Row],[Order_Date]]) -> 45175 | K46: Online | L46: Kolkata | M46: 1284.33
A47: 2047 | B47: Women | C47: Training | D47: SuperRep Go | E47: =IF(Nike_Sales_Uncleaned!E49="","NA",IF(OR(Nike_Sales_Uncleaned!E49=0,Nike_Sales_Uncleaned!E49=-1),"NA",UPPER(Nike_Sales_Uncleaned!E49))) -> 10 | F47: {=IF(Nike_Sales_Uncleaned!F49="",MEDIAN(_xlfn._xlws.FILTER(Nike_Sales_Uncleaned!$F$2:$F$2501,Nike_Sales_Uncleaned!$F$2:$F$2501>0)),Nike_Sales_Uncleaned!F49)} -> 1 | G47: {=IF(OR(Nike_Sales_Uncleaned!G49="",Nike_Sales_Uncleaned!G49<=0),MEDIAN(_xlfn._xlws.FILTER(Nike_Sales_Uncleaned!$G$2:$G$2501,Nike_Sales_Uncleaned!$G$2:$G$2501>0)),Nike_Sales_Uncleaned!G49)} -> 8577.75 | H47: =IF(Nike_Sales_Uncleaned!H49="",0,IF(AND(Nike_Sales_Uncleaned!H49>=0,Nike_Sales_Uncleaned!H49<=1),Nike_Sales_Uncleaned!H49,0)) -> 0 | I47: 0 | J47: =IF(Nike_Sales_Uncleaned[[#This Row],[Order_Date]]="","",Nike_Sales_Uncleaned[[#This Row],[Order_Date]]) -> 45753 | K47: Retail | L47: Bangalore | M47: 2888.68
A48: 2048 | B48: Women | C48: Basketball | D48: Air Jordan | E48: =IF(Nike_Sales_Uncleaned!E50="","NA",IF(OR(Nike_Sales_Uncleaned!E50=0,Nike_Sales_Uncleaned!E50=-1),"NA",UPPER(Nike_Sales_Uncleaned!E50))) -> XL | F48: {=IF(Nike_Sales_Uncleaned!F50="",MEDIAN(_xlfn._xlws.FILTER(Nike_Sales_Uncleaned!$F$2:$F$2501,Nike_Sales_Uncleaned!$F$2:$F$2501>0)),Nike_Sales_Uncleaned!F50)} -> 2 | G48: {=IF(OR(Nike_Sales_Uncleaned!G50="",Nike_Sales_Uncleaned!G50<=0),MEDIAN(_xlfn._xlws.FILTER(Nike_Sales_Uncleaned!$G$2:$G$2501,Nike_Sales_Uncleaned!$G$2:$G$2501>0)),Nike_Sales_Uncleaned!G50)} -> 6110.03 | H48: =IF(Nike_Sales_Uncleaned!H50="",0,IF(AND(Nike_Sales_Uncleaned!H50>=0,Nike_Sales_Uncleaned!H50<=1),Nike_Sales_Uncleaned!H50,0)) -> 0 | I48: 0 | J48: =IF(Nike_Sales_Uncleaned[[#This Row],[Order_Date]]="","",Nike_Sales_Uncleaned[[#This Row],[Order_Date]]) | K48: Online | L48: Bangalore | M48: 2875.86
A49: 2049 | B49: Kids | C49: Soccer | D49: Tiempo Legend | E49: =IF(Nike_Sales_Uncleaned!E51="","NA",IF(OR(Nike_Sales_Uncleaned!E51=0,Nike_Sales_Uncleaned!E51=-1),"NA",UPPER(Nike_Sales_Uncleaned!E51))) -> L | F49: {=IF(Nike_Sales_Uncleaned!F51="",MEDIAN(_xlfn._xlws.FILTER(Nike_Sales_Uncleaned!$F$2:$F$2501,Nike_Sales_Uncleaned!$F$2:$F$2501>0)),Nike_Sales_Uncleaned!F51)} -> 1 | G49: {=IF(OR(Nike_Sales_Uncleaned!G51="",Nike_Sales_Uncleaned!G51<=0),MEDIAN(_xlfn._xlws.FILTER(Nike_Sales_Uncleaned!$G$2:$G$2501,Nike_Sales_Uncleaned!$G$2:$G$2501>0)),Nike_Sales_Uncleaned!G51)} -> 7767.2 | H49: =IF(Nike_Sales_Uncleaned!H51="",0,IF(AND(Nike_Sales_Uncleaned!H51>=0,Nike_Sales_Uncleaned!H51<=1),Nike_Sales_Uncleaned!H51,0)) -> 0 | I49: 0 | J49: =IF(Nike_Sales_Uncleaned[[#This Row],[Order_Date]]="","",Nike_Sales_Uncleaned[[#This Row],[Order_Date]]) -> 45456 | K49: Retail | L49: Pune | M49: 311.48
A50: 2050 | B50: Men | C50: Running | D50: Air Zoom | E50: =IF(Nike_Sales_Uncleaned!E52="","NA",IF(OR(Nike_Sales_Uncleaned!E52=0,Nike_Sales_Uncleaned!E52=-1),"NA",UPPER(Nike_Sales_Uncleaned!E52))) -> L | F50: {=IF(Nike_Sales_Uncleaned!F52="",MEDIAN(_xlfn._xlws.FILTER(Nike_Sales_Uncleaned!$F$2:$F$2501,Nike_Sales_Uncleaned!$F$2:$F$2501>0)),Nike_Sales_Uncleaned!F52)} -> 1 | G50: {=IF(OR(Nike_Sales_Uncleaned!G52="",Nike_Sales_Uncleaned!G52<=0),MEDIAN(_xlfn._xlws.FILTER(Nike_Sales_Uncleaned!$G$2:$G$2501,Nike_Sales_Uncleaned!$G$2:$G$2501>0)),Nike_Sales_Uncleaned!G52)} -> 6110.03 | H50: =IF(Nike_Sales_Uncleaned!H52="",0,IF(AND(Nike_Sales_Uncleaned!H52>=0,Nike_Sales_Uncleaned!H52<=1),Nike_Sales_Uncleaned!H52,0)) -> 0.57 | I50: 0 | J50: =IF(Nike_Sales_Uncleaned[[#This Row],[Order_Date]]="","",Nike_Sales_Uncleaned[[#This Row],[Order_Date]]) -> 45592 | K50: Retail | L50: Kolkata | M50: 682.12
A51: 2051 | B51: Women | C51: Basketball | D51: Air Jordan | E51: =IF(Nike_Sales_Uncleaned!E53="","NA",IF(OR(Nike_Sales_Uncleaned!E53=0,Nike_Sales_Uncleaned!E53=-1),"NA",UPPER(Nike_Sales_Uncleaned!E53))) -> XL | F51: {=IF(Nike_Sales_Uncleaned!F53="",MEDIAN(_xlfn._xlws.FILTER(Nike_Sales_Uncleaned!$F$2:$F$2501,Nike_Sales_Uncleaned!$F$2:$F$2501>0)),Nike_Sales_Uncleaned!F53)} -> 2 | G51: {=IF(OR(Nike_Sales_Uncleaned!G53="",Nike_Sales_Uncleaned!G53<=0),MEDIAN(_xlfn._xlws.FILTER(Nike_Sales_Uncleaned!$G$2:$G$2501,Nike_Sales_Uncleaned!$G$2:$G$2501>0)),Nike_Sales_Uncleaned!G53)} -> 6110.03 | H51: =IF(Nike_Sales_Uncleaned!H53="",0,IF(AND(Nike_Sales_Uncleaned!H53>=0,Nike_Sales_Uncleaned!H53<=1),Nike_Sales_Uncleaned!H53,0)) -> 0.37 | I51: 0 | J51: =IF(Nike_Sales_Uncleaned[[#This Row],[Order_Date]]="","",Nike_Sales_Uncleaned[[#This Row],[Order_Date]]) | K51: Retail | L51: Delhi | M51: 3135.98
A52: 2052 | B52: Men | C52: Training | D52: Flex Trainer | E52: =IF(Nike_Sales_Uncleaned!E54="","NA",IF(OR(Nike_Sales_Uncleaned!E54=0,Nike_Sales_Uncleaned!E54=-1),"NA",UPPER(Nike_Sales_Uncleaned!E54))) -> 10 | F52: {=IF(Nike_Sales_Uncleaned!F54="",MEDIAN(_xlfn._xlws.FILTER(Nike_Sales_Uncleaned!$F$2:$F$2501,Nike_Sales_Uncleaned!$F$2:$F$2501>0)),Nike_Sales_Uncleaned!F54)} -> 3 | G52: {=IF(OR(Nike_Sales_Uncleaned!G54="",Nike_Sales_Uncleaned!G54<=0),MEDIAN(_xlfn._xlws.FILTER(Nike_Sales_Uncleaned!$G$2:$G$2501,Nike_Sales_Uncleaned!$G$2:$G$2501>0)),Nike_Sales_Uncleaned!G54)} -> 9155.96 | H52: =IF(Nike_Sales_Uncleaned!H54="",0,IF(AND(Nike_Sales_Uncleaned!H54>=0,Nike_Sales_Uncleaned!H54<=1),Nike_Sales_Uncleaned!H54,0)) -> 0 | I52: 0 | J52: =IF(Nike_Sales_Uncleaned[[#This Row],[Order_Date]]="","",Nike_Sales_Uncleaned[[#This Row],[Order_Date]]) | K52: Retail | L52: Pune | M52: 2184.8
... A56: 2056 | B56: Men | C56: Running | D56: React Infinity | E56: =IF(Nike_Sales_Uncleaned!E58="","NA",IF(OR(Nike_Sales_Uncleaned!E58=0,Nike_Sales_Uncleaned!E58=-1),"NA",UPPER(Nike_Sales_Uncleaned!E58))) -> L | F56: {=IF(Nike_Sales_Uncleaned!F58="",MEDIAN(_xlfn._xlws.FILTER(Nike_Sales_Uncleaned!$F$2:$F$2501,Nike_Sales_Uncleaned!$F$2:$F$2501>0)),Nike_Sales_Uncleaned!F58)} -> 3 | G56: {=IF(OR(Nike_Sales_Uncleaned!G58="",Nike_Sales_Uncleaned!G58<=0),MEDIAN(_xlfn._xlws.FILTER(Nike_Sales_Uncleaned!$G$2:$G$2501,Nike_Sales_Uncleaned!$G$2:$G$2501>0)),Nike_Sales_Uncleaned!G58)} -> 6110.03 | H56: =IF(Nike_Sales_Uncleaned!H58="",0,IF(AND(Nike_Sales_Uncleaned!H58>=0,Nike_Sales_Uncleaned!H58<=1),Nike_Sales_Uncleaned!H58,0)) -> 0 | I56: 0 | J56: =IF(Nike_Sales_Uncleaned[[#This Row],[Order_Date]]="","",Nike_Sales_Uncleaned[[#This Row],[Order_Date]]) -> 45831 | K56: Retail | L56: Bangalore | M56: -244.44
...

Sheet Pivot Tables
B8: Sales by Product Line | E8: Sales by Region | I8: Sales By Gender
B9: Row Labels | C9: Sum of Revenue | E9: Row Labels | F9: Sum of Revenue | G9: Sum of Profit | I9: Row Labels | J9: Sum of Revenue | K9: Sum of Units_Sold
B10: Basketball | C10: 159372.33 | E10: Bangalore | F10: 102745.56 | G10: 608017.7 | I10: Kids | J10: 196029.84 | K10: 1394
B11: Lifestyle | C11: 136624.33 | E11: Delhi | F11: 97181.96 | G11: 560808.32 | I11: Men | J11: 262493.77 | K11: 1406
B12: Running | C12: 72075.95 | E12: Hyderabad | F12: 126847.67 | G12: 498376.83 | I12: Women | J12: 219942.99 | K12: 1340
B13: Soccer | C13: 114213.03 | E13: Kolkata | F13: 156634 | G13: 568729.41 | I13: Grand Total | J13: 678466.6 | K13: 4140
B14: Training | C14: 196180.96 | E14: Mumbai | F14: 93880.14 | G14: 555487.9
B15: Grand Total | C15: 678466.6 | E15: Pune | F15: 101177.27 | G15: 521704.46
E16: Grand Total | F16: 678466.6 | G16: 3313124.6
F20: Sales by Year And Month
F21: Row Labels | G21: Sum of Units_Sold | H21: Sum of Revenue
F22: <26-07-2023 | G22: 968 | H22: 139909.65
F23: 2023 | G23: 177 | H23: 43945.34
F24: 2024 | G24: 1544 | H24: 254762.53
F25: 2025 | G25: 1451 | H25: 239849.08
F26: Grand Total | G26: 4140 | H26: 678466.6

Sheet Fact_Sales
A1: Sales_ID | B1: Order_ID | C1: Product_Key | D1: Date_key_0 | E1: Region_key | F1: Channel_Key | G1: Gender_key | H1: Units_Sold | I1: MRP | J1: Discount_Applied | K1: Revenue | L1: Profit | M1: Product_Name | N1: Product_Line | O1: Size | P1: Product_temp | Q1: Order_Date | R1: Region | S1: Channel | T1: Gender_category | U1: Date_key | V1: Column2 | W1: Column1
A2: SID-01 | B2: =Cleaned_Data[[#This Row],[Order_ID]] -> 2000 | C2: =_xlfn.XLOOKUP(P2,Dim_Product!$E$2:$E$221,Dim_Product!$A$2:$A$221,"Not Found") -> PK-01 | D2: =_xlfn.XLOOKUP(Table5[[#This Row],[Order_Date]],Table8[Date],Table8[Date_Key],"") -> DK-228 | E2: =_xlfn.XLOOKUP(R2,Table4[Region],Table4[Region_Key]) -> RK-01 | F2: =_xlfn.XLOOKUP(S2,Table6[Sales_Channel],Table6[Channel_Key]) -> CK-01 | G2: =_xlfn.XLOOKUP(T2,Table7[Gender_Category],Table7[Gender_Key]) -> GK-01 | H2: =Cleaned_Data[[#This Row],[Units_Sold]] -> 2 | I2: =Cleaned_Data[[#This Row],[MRP]] -> 6110.03 | J2: =Cleaned_Data[[#This Row],[Discount_Applied]] -> 0.47 | K2: =Cleaned_Data[[#This Row],[Revenue]] -> 0 | L2: =Cleaned_Data[[#This Row],[Profit]] -> -770.45 | M2: =Cleaned_Data[[#This Row],[Product_Name]] -> SuperRep Go | N2: =Cleaned_Data[[#This Row],[Product_Line]] -> Training | O2: =Cleaned_Data[[#This Row],[Size]] -> M | P2: =TRIM(M2)&"|"&TRIM(N2)&"|"&TRIM(O2) -> SuperRep Go|Training|M | Q2: =Cleaned_Data[[#This Row],[Order_Date]] -> 45360 | R2: =Cleaned_Data[[#This Row],[Region]] -> Bangalore | S2: =Cleaned_Data[[#This Row],[Sales_Channel]] -> Online | T2: =Cleaned_Data[[#This Row],[Gender_Category]] -> Kids | U2: =IF(D2="",0,D2) -> DK-228
A3: SID-02 | B3: =Cleaned_Data[[#This Row],[Order_ID]] -> 2001 | C3: =_xlfn.XLOOKUP(P3,Dim_Product!$E$2:$E$221,Dim_Product!$A$2:$A$221,"Not Found") -> PK-02 | D3: =_xlfn.XLOOKUP(Table5[[#This Row],[Order_Date]],Table8[Date],Table8[Date_Key],"Not Found") -> DK-350 | E3: =_xlfn.XLOOKUP(R3,Table4[Region],Table4[Region_Key]) -> RK-02 | F3: =_xlfn.XLOOKUP(S3,Table6[Sales_Channel],Table6[Channel_Key]) -> CK-02 | G3: =_xlfn.XLOOKUP(T3,Table7[Gender_Category],Table7[Gender_Key]) -> GK-02 | H3: =Cleaned_Data[[#This Row],[Units_Sold]] -> 3 | I3: =Cleaned_Data[[#This Row],[MRP]] -> 4957.93 | J3: =Cleaned_Data[[#This Row],[Discount_Applied]] -> 0 | K3: =Cleaned_Data[[#This Row],[Revenue]] -> 0 | L3: =Cleaned_Data[[#This Row],[Profit]] -> -112.53 | M3: =Cleaned_Data[[#This Row],[Product_Name]] -> Tiempo Legend | N3: =Cleaned_Data[[#This Row],[Product_Line]] -> Soccer | O3: =Cleaned_Data[[#This Row],[Size]] -> M | P3: =TRIM(M3)&"|"&TRIM(N3)&"|"&TRIM(O3) -> Tiempo Legend|Soccer|M | Q3: =Cleaned_Data[[#This Row],[Order_Date]] -> 45482 | R3: =Cleaned_Data[[#This Row],[Region]] -> Hyderabad | S3: =Cleaned_Data[[#This Row],[Sales_Channel]] -> Retail | T3: =Cleaned_Data[[#This Row],[Gender_Category]] -> Women | U3: =IF(D3="",0,D3) -> DK-350
A4: SID-03 | B4: =Cleaned_Data[[#This Row],[Order_ID]] -> 2002 | C4: =_xlfn.XLOOKUP(P4,Dim_Product!$E$2:$E$221,Dim_Product!$A$2:$A$221,"Not Found") -> PK-03 | D4: =_xlfn.XLOOKUP(Table5[[#This Row],[Order_Date]],Table8[Date],Table8[Date_Key],"Not Found") -> Not Found | E4: =_xlfn.XLOOKUP(R4,Table4[Region],Table4[Region_Key]) -> RK-03 | F4: =_xlfn.XLOOKUP(S4,Table6[Sales_Channel],Table6[Channel_Key]) -> CK-02 | G4: =_xlfn.XLOOKUP(T4,Table7[Gender_Category],Table7[Gender_Key]) -> GK-02 | H4: =Cleaned_Data[[#This Row],[Units_Sold]] -> 4 | I4: =Cleaned_Data[[#This Row],[MRP]] -> 6110.03 | J4: =Cleaned_Data[[#This Row],[Discount_Applied]] -> 0 | K4: =Cleaned_Data[[#This Row],[Revenue]] -> 0 | L4: =Cleaned_Data[[#This Row],[Profit]] -> 3337.34 | M4: =Cleaned_Data[[#This Row],[Product_Name]] -> Premier III | N4: =Cleaned_Data[[#This Row],[Product_Line]] -> Soccer | O4: =Cleaned_Data[[#This Row],[Size]] -> M | P4: =TRIM(M4)&"|"&TRIM(N4)&"|"&TRIM(O4) -> Premier III|Soccer|M | Q4: =Cleaned_Data[[#This Row],[Order_Date]] | R4: =Cleaned_Data[[#This Row],[Region]] -> Mumbai | S4: =Cleaned_Data[[#This Row],[Sales_Channel]] -> Retail | T4: =Cleaned_Data[[#This Row],[Gender_Category]] -> Women | U4: =IF(D4="",0,D4) -> Not Found
A5: SID-04 | B5: =Cleaned_Data[[#This Row],[Order_ID]] -> 2003 | C5: =_xlfn.XLOOKUP(P5,Dim_Product!$E$2:$E$221,Dim_Product!$A$2:$A$221,"Not Found") -> PK-04 | D5: =_xlfn.XLOOKUP(Table5[[#This Row],[Order_Date]],Table8[Date],Table8[Date_Key],"Not Found") -> DK-437 | E5: =_xlfn.XLOOKUP(R5,Table4[Region],Table4[Region_Key]) -> RK-04 | F5: =_xlfn.XLOOKUP(S5,Table6[Sales_Channel],Table6[Channel_Key]) -> CK-01 | G5: =_xlfn.XLOOKUP(T5,Table7[Gender_Category],Table7[Gender_Key]) -> GK-01 | H5: =Cleaned_Data[[#This Row],[Units_Sold]] -> 2 | I5: =Cleaned_Data[[#This Row],[MRP]] -> 9673.57 | J5: =Cleaned_Data[[#This Row],[Discount_Applied]] -> 0 | K5: =Cleaned_Data[[#This Row],[Revenue]] -> 0 | L5: =Cleaned_Data[[#This Row],[Profit]] -> 3376.85 | M5: =Cleaned_Data[[#This Row],[Product_Name]] -> Blazer Mid | N5: =Cleaned_Data[[#This Row],[Product_Line]] -> Lifestyle | O5: =Cleaned_Data[[#This Row],[Size]] -> L | P5: =TRIM(M5)&"|"&TRIM(N5)&"|"&TRIM(O5) -> Blazer Mid|Lifestyle|L | Q5: =Cleaned_Data[[#This Row],[Order_Date]] -> 45569 | R5: =Cleaned_Data[[#This Row],[Region]] -> Pune | S5: =Cleaned_Data[[#This Row],[Sales_Channel]] -> Online | T5: =Cleaned_Data[[#This Row],[Gender_Category]] -> Kids | U5: =IF(D5="",0,D5) -> DK-437
A6: SID-05 | B6: =Cleaned_Data[[#This Row],[Order_ID]] -> 2004 | C6: =_xlfn.XLOOKUP(P6,Dim_Product!$E$2:$E$221,Dim_Product!$A$2:$A$221,"Not Found") -> PK-05 | D6: =_xlfn.XLOOKUP(Table5[[#This Row],[Order_Date]],Table8[Date],Table8[Date_Key],"Not Found") -> DK-415 | E6: =_xlfn.XLOOKUP(R6,Table4[Region],Table4[Region_Key]) -> RK-05 | F6: =_xlfn.XLOOKUP(S6,Table6[Sales_Channel],Table6[Channel_Key]) -> CK-02 | G6: =_xlfn.XLOOKUP(T6,Table7[Gender_Category],Table7[Gender_Key]) -> GK-01 | H6: =Cleaned_Data[[#This Row],[Units_Sold]] -> 2 | I6: =Cleaned_Data[[#This Row],[MRP]] -> 6110.03 | J6: =Cleaned_Data[[#This Row],[Discount_Applied]] -> 0 | K6: =Cleaned_Data[[#This Row],[Revenue]] -> 0 | L6: =Cleaned_Data[[#This Row],[Profit]] -> 187.89 | M6: =Cleaned_Data[[#This Row],[Product_Name]] -> React Infinity | N6: =Cleaned_Data[[#This Row],[Product_Line]] -> Running | O6: =Cleaned_Data[[#This Row],[Size]] -> XL | P6: =TRIM(M6)&"|"&TRIM(N6)&"|"&TRIM(O6) -> React Infinity|Running|XL | Q6: =Cleaned_Data[[#This Row],[Order_Date]] -> 45547 | R6: =Cleaned_Data[[#This Row],[Region]] -> Delhi | S6: =Cleaned_Data[[#This Row],[Sales_Channel]] -> Retail | T6: =Cleaned_Data[[#This Row],[Gender_Category]] -> Kids | U6: =IF(D6="",0,D6) -> DK-415
A7: SID-06 | B7: =Cleaned_Data[[#This Row],[Order_ID]] -> 2005 | C7: =_xlfn.XLOOKUP(P7,Dim_Product!$E$2:$E$221,Dim_Product!$A$2:$A$221,"Not Found") -> PK-06 | D7: =_xlfn.XLOOKUP(Table5[[#This Row],[Order_Date]],Table8[Date],Table8[Date_Key],"Not Found") -> Not Found | E7: =_xlfn.XLOOKUP(R7,Table4[Region],Table4[Region_Key]) -> RK-05 | F7: =_xlfn.XLOOKUP(S7,Table6[Sales_Channel],Table6[Channel_Key]) -> CK-02 | G7: =_xlfn.XLOOKUP(T7,Table7[Gender_Category],Table7[Gender_Key]) -> GK-02 | H7: =Cleaned_Data[[#This Row],[Units_Sold]] -> 1 | I7: =Cleaned_Data[[#This Row],[MRP]] -> 7363.96 | J7: =Cleaned_Data[[#This Row],[Discount_Applied]] -> 0 | K7: =Cleaned_Data[[#This Row],[Revenue]] -> 0 | L7: =Cleaned_Data[[#This Row],[Profit]] -> 1415.98 | M7: =Cleaned_Data[[#This Row],[Product_Name]] -> Flex Trainer | N7: =Cleaned_Data[[#This Row],[Product_Line]] -> Training | O7: =Cleaned_Data[[#This Row],[Size]] -> M | P7: =TRIM(M7)&"|"&TRIM(N7)&"|"&TRIM(O7) -> Flex Trainer|Training|M | Q7: =Cleaned_Data[[#This Row],[Order_Date]] | R7: =Cleaned_Data[[#This Row],[Region]] -> Delhi | S7: =Cleaned_Data[[#This Row],[Sales_Channel]] -> Retail | T7: =Cleaned_Data[[#This Row],[Gender_Category]] -> Women | U7: =IF(D7="",0,D7) -> Not Found
A8: SID-07 | B8: =Cleaned_Data[[#This Row],[Order_ID]] -> 2006 | C8: =_xlfn.XLOOKUP(P8,Dim_Product!$E$2:$E$221,Dim_Product!$A$2:$A$221,"Not Found") -> PK-01 | D8: =_xlfn.XLOOKUP(Table5[[#This Row],[Order_Date]],Table8[Date],Table8[Date_Key],"Not Found") -> DK-680 | E8: =_xlfn.XLOOKUP(R8,Table4[Region],Table4[Region_Key]) -> RK-01 | F8: =_xlfn.XLOOKUP(S8,Table6[Sales_Channel],Table6[Channel_Key]) -> CK-01 | G8: =_xlfn.XLOOKUP(T8,Table7[Gender_Category],Table7[Gender_Key]) -> GK-03 | H8: =Cleaned_Data[[#This Row],[Units_Sold]] -> 2 | I8: =Cleaned_Data[[#This Row],[MRP]] -> 6819.78 | J8: =Cleaned_Data[[#This Row],[Discount_Applied]] -> 0 | K8: =Cleaned_Data[[#This Row],[Revenue]] -> 0 | L8: =Cleaned_Data[[#This Row],[Profit]] -> 1802.09 | M8: =Cleaned_Data[[#This Row],[Product_Name]] -> SuperRep Go | N8: =Cleaned_Data[[#This Row],[Product_Line]] -> Training | O8: =Cleaned_Data[[#This Row],[Size]] -> M | P8: =TRIM(M8)&"|"&TRIM(N8)&"|"&TRIM(O8) -> SuperRep Go|Training|M | Q8: =Cleaned_Data[[#This Row],[Order_Date]] -> 45812 | R8: =Cleaned_Data[[#This Row],[Region]] -> Bangalore | S8: =Cleaned_Data[[#This Row],[Sales_Channel]] -> Online | T8: =Cleaned_Data[[#This Row],[Gender_Category]] -> Men | U8: =IF(D8="",0,D8) -> DK-680
A9: SID-08 | B9: =Cleaned_Data[[#This Row],[Order_ID]] -> 2007 | C9: =_xlfn.XLOOKUP(P9,Dim_Product!$E$2:$E$221,Dim_Product!$A$2:$A$221,"Not Found") -> PK-01 | D9: =_xlfn.XLOOKUP(Table5[[#This Row],[Order_Date]],Table8[Date],Table8[Date_Key],"Not Found") -> Not Found | E9: =_xlfn.XLOOKUP(R9,Table4[Region],Table4[Region_Key]) -> RK-01 | F9: =_xlfn.XLOOKUP(S9,Table6[Sales_Channel],Table6[Channel_Key]) -> CK-02 | G9: =_xlfn.XLOOKUP(T9,Table7[Gender_Category],Table7[Gender_Key]) -> GK-01 | H9: =Cleaned_Data[[#This Row],[Units_Sold]] -> 1 | I9: =Cleaned_Data[[#This Row],[MRP]] -> 6110.03 | J9: =Cleaned_Data[[#This Row],[Discount_Applied]] -> 0.32 | K9: =Cleaned_Data[[#This Row],[Revenue]] -> 0 | L9: =Cleaned_Data[[#This Row],[Profit]] -> 2928.36 | M9: =Cleaned_Data[[#This Row],[Product_Name]] -> SuperRep Go | N9: =Cleaned_Data[[#This Row],[Product_Line]] -> Training | O9: =Cleaned_Data[[#This Row],[Size]] -> M | P9: =TRIM(M9)&"|"&TRIM(N9)&"|"&TRIM(O9) -> SuperRep Go|Training|M | Q9: =Cleaned_Data[[#This Row],[Order_Date]] | R9: =Cleaned_Data[[#This Row],[Region]] -> Bangalore | S9: =Cleaned_Data[[#This Row],[Sales_Channel]] -> Retail | T9: =Cleaned_Data[[#This Row],[Gender_Category]] -> Kids | U9: =IF(D9="",0,D9) -> Not Found
A10: SID-09 | B10: =Cleaned_Data[[#This Row],[Order_ID]] -> 2008 | C10: =_xlfn.XLOOKUP(P10,Dim_Product!$E$2:$E$221,Dim_Product!$A$2:$A$221,"Not Found") -> PK-07 | D10: =_xlfn.XLOOKUP(Table5[[#This Row],[Order_Date]],Table8[Date],Table8[Date_Key],"Not Found") -> DK-444 | E10: =_xlfn.XLOOKUP(R10,Table4[Region],Table4[Region_Key]) -> RK-02 | F10: =_xlfn.XLOOKUP(S10,Table6[Sales_Channel],Table6[Channel_Key]) -> CK-01 | G10: =_xlfn.XLOOKUP(T10,Table7[Gender_Category],Table7[Gender_Key]) -> GK-02 | H10: =Cleaned_Data[[#This Row],[Units_Sold]] -> -1 | I10: =Cleaned_Data[[#This Row],[MRP]] -> 6110.03 | J10: =Cleaned_Data[[#This Row],[Discount_Applied]] -> 0 | K10: =Cleaned_Data[[#This Row],[Revenue]] -> 0 | L10: =Cleaned_Data[[#This Row],[Profit]] -> -731.18 | M10: =Cleaned_Data[[#This Row],[Product_Name]] -> Premier III | N10: =Cleaned_Data[[#This Row],[Product_Line]] -> Soccer | O10: =Cleaned_Data[[#This Row],[Size]] -> 11 | P10: =TRIM(M10)&"|"&TRIM(N10)&"|"&TRIM(O10) -> Premier III|Soccer|11 | Q10: =Cleaned_Data[[#This Row],[Order_Date]] -> 45576 | R10: =Cleaned_Data[[#This Row],[Region]] -> Hyderabad | S10: =Cleaned_Data[[#This Row],[Sales_Channel]] -> Online | T10: =Cleaned_Data[[#This Row],[Gender_Category]] -> Women | U10: =IF(D10="",0,D10) -> DK-444
A11: SID-10 | B11: =Cleaned_Data[[#This Row],[Order_ID]] -> 2009 | C11: =_xlfn.XLOOKUP(P11,Dim_Product!$E$2:$E$221,Dim_Product!$A$2:$A$221,"Not Found") -> PK-08 | D11: =_xlfn.XLOOKUP(Table5[[#This Row],[Order_Date]],Table8[Date],Table8[Date_Key],"Not Found") -> Not Found | E11: =_xlfn.XLOOKUP(R11,Table4[Region],Table4[Region_Key]) -> RK-04 | F11: =_xlfn.XLOOKUP(S11,Table6[Sales_Channel],Table6[Channel_Key]) -> CK-01 | G11: =_xlfn.XLOOKUP(T11,Table7[Gender_Category],Table7[Gender_Key]) -> GK-03 | H11: =Cleaned_Data[[#This Row],[Units_Sold]] -> 4 | I11: =Cleaned_Data[[#This Row],[MRP]] -> 6110.03 | J11: =Cleaned_Data[[#This Row],[Discount_Applied]] -> 0 | K11: =Cleaned_Data[[#This Row],[Revenue]] -> 0 | L11: =Cleaned_Data[[#This Row],[Profit]] -> 3929.61 | M11: =Cleaned_Data[[#This Row],[Product_Name]] -> Mercurial Superfly | N11: =Cleaned_Data[[#This Row],[Product_Line]] -> Soccer | O11: =Cleaned_Data[[#This Row],[Size]] -> M | P11: =TRIM(M11)&"|"&TRIM(N11)&"|"&TRIM(O11) -> Mercurial Superfly|Soccer|M | Q11: =Cleaned_Data[[#This Row],[Order_Date]] | R11: =Cleaned_Data[[#This Row],[Region]] -> Pune | S11: =Cleaned_Data[[#This Row],[Sales_Channel]] -> Online | T11: =Cleaned_Data[[#This Row],[Gender_Category]] -> Men | U11: =IF(D11="",0,D11) -> Not Found
A12: SID-11 | B12: =Cleaned_Data[[#This Row],[Order_ID]] -> 2010 | C12: =_xlfn.XLOOKUP(P12,Dim_Product!$E$2:$E$221,Dim_Product!$A$2:$A$221,"Not Found") -> PK-09 | D12: =_xlfn.XLOOKUP(Table5[[#This Row],[Order_Date]],Table8[Date],Table8[Date_Key],"Not Found") -> DK-541 | E12: =_xlfn.XLOOKUP(R12,Table4[Region],Table4[Region_Key]) -> RK-04 | F12: =_xlfn.XLOOKUP(S12,Table6[Sales_Channel],Table6[Channel_Key]) -> CK-01 | G12: =_xlfn.XLOOKUP(T12,Table7[Gender_Category],Table7[Gender_Key]) -> GK-01 | H12: =Cleaned_Data[[#This Row],[Units_Sold]] -> 1 | I12: =Cleaned_Data[[#This Row],[MRP]] -> 7949.83 | J12: =Cleaned_Data[[#This Row],[Discount_Applied]] -> 0 | K12: =Cleaned_Data[[#This Row],[Revenue]] -> 0 | L12: =Cleaned_Data[[#This Row],[Profit]] -> 1965.56 | M12: =Cleaned_Data[[#This Row],[Product_Name]] -> Waffle One | N12: =Cleaned_Data[[#This Row],[Product_Line]] -> Lifestyle | O12: =Cleaned_Data[[#This Row],[Size]] -> L | P12: =TRIM(M12)&"|"&TRIM(N12)&"|"&TRIM(O12) -> Waffle One|Lifestyle|L | Q12: =Cleaned_Data[[#This Row],[Order_Date]] -> 45673 | R12: =Cleaned_Data[[#This Row],[Region]] -> Pune | S12: =Cleaned_Data[[#This Row],[Sales_Channel]] -> Online | T12: =Cleaned_Data[[#This Row],[Gender_Category]] -> Kids | U12: =IF(D12="",0,D12) -> DK-541
A13: SID-12 | B13: =Cleaned_Data[[#This Row],[Order_ID]] -> 2011 | C13: =_xlfn.XLOOKUP(P13,Dim_Product!$E$2:$E$221,Dim_Product!$A$2:$A$221,"Not Found") -> PK-10 | D13: =_xlfn.XLOOKUP(Table5[[#This Row],[Order_Date]],Table8[Date],Table8[Date_Key],"Not Found") -> Not Found | E13: =_xlfn.XLOOKUP(R13,Table4[Region],Table4[Region_Key]) -> RK-02 | F13: =_xlfn.XLOOKUP(S13,Table6[Sales_Channel],Table6[Channel_Key]) -> CK-02 | G13: =_xlfn.XLOOKUP(T13,Table7[Gender_Category],Table7[Gender_Key]) -> GK-02 | H13: =Cleaned_Data[[#This Row],[Units_Sold]] -> -1 | I13: =Cleaned_Data[[#This Row],[MRP]] -> 9586.08 | J13: =Cleaned_Data[[#This Row],[Discount_Applied]] -> 0 | K13: =Cleaned_Data[[#This Row],[Revenue]] -> 0 | L13: =Cleaned_Data[[#This Row],[Profit]] -> 1667.08 | M13: =Cleaned_Data[[#This Row],[Product_Name]] -> Flex Trainer | N13: =Cleaned_Data[[#This Row],[Product_Line]] -> Training | O13: =Cleaned_Data[[#This Row],[Size]] -> L | P13: =TRIM(M13)&"|"&TRIM(N13)&"|"&TRIM(O13) -> Flex Trainer|Training|L | Q13: =Cleaned_Data[[#This Row],[Order_Date]] | R13: =Cleaned_Data[[#This Row],[Region]] -> Hyderabad | S13: =Cleaned_Data[[#This Row],[Sales_Channel]] -> Retail | T13: =Cleaned_Data[[#This Row],[Gender_Category]] -> Women | U13: =IF(D13="",0,D13) -> Not Found
A14: SID-13 | B14: =Cleaned_Data[[#This Row],[Order_ID]] -> 2018 | C14: =_xlfn.XLOOKUP(P14,Dim_Product!$E$2:$E$221,Dim_Product!$A$2:$A$221,"Not Found") -> PK-11 | D14: =_xlfn.XLOOKUP(Table5[[#This Row],[Order_Date]],Table8[Date],Table8[Date_Key],"Not Found") -> DK-477 | E14: =_xlfn.XLOOKUP(R14,Table4[Region],Table4[Region_Key]) -> RK-05 | F14: =_xlfn.XLOOKUP(S14,Table6[Sales_Channel],Table6[Channel_Key]) -> CK-01 | G14: =_xlfn.XLOOKUP(T14,Table7[Gender_Category],Table7[Gender_Key]) -> GK-01 | H14: =Cleaned_Data[[#This Row],[Units_Sold]] -> -1 | I14: =Cleaned_Data[[#This Row],[MRP]] -> 6110.03 | J14: =Cleaned_Data[[#This Row],[Discount_Applied]] -> 0.86 | K14: =Cleaned_Data[[#This Row],[Revenue]] -> 0 | L14: =Cleaned_Data[[#This Row],[Profit]] -> 2109.48 | M14: =Cleaned_Data[[#This Row],[Product_Name]] -> Blazer Mid | N14: =Cleaned_Data[[#This Row],[Product_Line]] -> Lifestyle | O14: =Cleaned_Data[[#This Row],[Size]] -> NA | P14: =TRIM(M14)&"|"&TRIM(N14)&"|"&TRIM(O14) -> Blazer Mid|Lifestyle|NA | Q14: =Cleaned_Data[[#This Row],[Order_Date]] -> 45609 | R14: =Cleaned_Data[[#This Row],[Region]] -> Delhi | S14: =Cleaned_Data[[#This Row],[Sales_Channel]] -> Online | T14: =Cleaned_Data[[#This Row],[Gender_Category]] -> Kids | U14: =IF(D14="",0,D14) -> DK-477
... A2387: SID-2386 | B2387: =Cleaned_Data[[#This Row],[Order_ID]] -> 4499 | C2387: =_xlfn.XLOOKUP(P2387,Dim_Product!$E$2:$E$221,Dim_Product!$A$2:$A$221,"Not Found") -> PK-114 | D2387: =_xlfn.XLOOKUP(Table5[[#This Row],[Order_Date]],Table8[Date],Table8[Date_Key],"Not Found") -> DK-141 | E2387: =_xlfn.XLOOKUP(R2387,Table4[Region],Table4[Region_Key]) -> RK-03 | F2387: =_xlfn.XLOOKUP(S2387,Table6[Sales_Channel],Table6[Channel_Key]) -> CK-02 | G2387: =_xlfn.XLOOKUP(T2387,Table7[Gender_Category],Table7[Gender_Key]) -> GK-02 | H2387: =Cleaned_Data[[#This Row],[Units_Sold]] -> 2 | I2387: =Cleaned_Data[[#This Row],[MRP]] -> 5550.99 | J2387: =Cleaned_Data[[#This Row],[Discount_Applied]] -> 0 | K2387: =Cleaned_Data[[#This Row],[Revenue]] -> 0 | L2387: =Cleaned_Data[[#This Row],[Profit]] -> 2453.57 | M2387: =Cleaned_Data[[#This Row],[Product_Name]] -> Air Zoom | N2387: =Cleaned_Data[[#This Row],[Product_Line]] -> Running | O2387: =Cleaned_Data[[#This Row],[Size]] -> M | P2387: =TRIM(M2387)&"|"&TRIM(N2387)&"|"&TRIM(O2387) -> Air Zoom|Running|M | Q2387: =Cleaned_Data[[#This Row],[Order_Date]] -> 45273 | R2387: =Cleaned_Data[[#This Row],[Region]] -> Mumbai | S2387: =Cleaned_Data[[#This Row],[Sales_Channel]] -> Retail | T2387: =Cleaned_Data[[#This Row],[Gender_Category]] -> Women | U2387: =IF(D2387="",0,D2387) -> DK-141

Sheet Dim_Product
